Workbook
Name NativeTimeline_Date: #N/A
Name Slicer_Region: #N/A

Sheet Project Instuctions
A1: PR. Final Project - "Data Intelligence Dashboard"
A2: Dataset: Use the 'Final Project Dataset' sheet containing 200+ records of customer transactions.
A4: Objective:
A5: Create a full-fledged analysis and reporting solution using Excel to analyze customer transactions, find insights,
A6: and build visualizations and dashboards.
A8: Key Topics to Implement:
A9: - Date & Time Functions: TODAY, NOW, DATEDIF, EOMONTH
A10: - FILTER Function for multi-value returns
A11: - Conditional Formatting with Icons/Arrows
A12: - Create Timestamp (using NOW and iterative calculations)
A13: - WHAT-IF Analysis: Scenario Manager, Goal Seek
A14: - Linear Regression using Data Analysis Toolpak
A15: - Data Analysis & Storytelling from the dataset
A16: {=- Use GroupBy concepts to find High-value Customers using formulas} -> #NAME?
A17: - Create Dashboard using:
A18: - Pivot Tables
A19: - Pivot Charts (Bar, Line, Pie)
A20: - Slicers and Timelines
A21: - KPI Indicators with Conditional Formatting
A22: - Find most frequently purchased product or repeating names using formulas
A23: - Compare two lists and extract matching names in a new column
A24: - Create Abbreviations using TEXT functions
A25: - Build a final report with insights and storytelling
A27: Deliverable:
A28: - Well-structured workbook with multiple sheets (Raw Data, Analysis, Visualizations, Dashboard)
A29: - Summary insights with key metrics: Total Revenue, Top Customers, most Sold Products, Regional Sales
A30: - Use of all required formulas and functions as listed above

Sheet Final Project Dataset
A1: Transaction_ID | B1: Date | C1: Customer_ID | D1: Customer_Name | E1: Product_ID | F1: Product_Name | G1: Category | H1: Quantity | I1: Unit_Price | J1: Payment_Method | K1: Region | L1: Customer_Segment | M1: Customer_Since | N1: Total_Amount
A2: TRX0155 | B2: 45393 | C2: CUST023 | D2: Paul Baker | E2: P009 | F2: Monitor | G2: Electronics | H2: 3 | I2: 249.99 | J2: Cash | K2: Central | L2: Basic | M2: 44425 | N2: 749.97
A3: TRX0023 | B3: 45396 | C3: CUST013 | D3: Joseph Jackson | E3: P009 | F3: Monitor | G3: Electronics | H3: 3 | I3: 249.99 | J3: Credit Card | K3: Central | L3: Premium | M3: 44575 | N3: 749.97
A4: TRX0139 | B4: 45399 | C4: CUST021 | D4: Kevin Scott | E4: P005 | F4: Blender | G4: Appliances | H4: 3 | I4: 59.99 | J4: PayPal | K4: South | L4: Standard | M4: 45262 | N4: 179.97
A5: TRX0043 | B5: 45400 | C5: CUST046 | D5: Kathleen Bennett | E5: P005 | F5: Blender | G5: Appliances | H5: 3 | I5: 59.99 | J5: Cash | K5: North | L5: Premium | M5: 45114 | N5: 179.97
A6: TRX0212 | B6: 45400 | C6: CUST003 | D6: Michael Brown | E6: P008 | F6: Bookshelf | G6: Furniture | H6: 5 | I6: 149.99 | J6: Credit Card | K6: North | L6: Premium | M6: 45295 | N6: 749.95
A7: TRX0092 | B7: 45403 | C7: CUST024 | D7: Dorothy Nelson | E7: P005 | F7: Blender | G7: Appliances | H7: 2 | I7: 59.99 | J7: Cash | K7: West | L7: Standard | M7: 44746 | N7: 119.98
A8: TRX0193 | B8: 45403 | C8: CUST024 | D8: Dorothy Nelson | E8: P003 | F8: Headphones | G8: Electronics | H8: 5 | I8: 149.99 | J8: Credit Card | K8: Central | L8: Standard | M8: 44418 | N8: 749.95
A9: TRX0240 | B9: 45403 | C9: CUST017 | D9: Charles Allen | E9: P005 | F9: Blender | G9: Appliances | H9: 3 | I9: 59.99 | J9: Debit Card | K9: South | L9: Basic | M9: 45007 | N9: 179.97
A10: TRX0135 | B10: 45405 | C10: CUST009 | D10: Robert Thomas | E10: P001 | F10: Laptop | G10: Electronics | H10: 3 | I10: 899.99 | J10: PayPal | K10: East | L10: Standard | M10: 45299 | N10: 2699.97
A11: TRX0185 | B11: 45408 | C11: CUST026 | D11: Karen Hill | E11: P005 | F11: Blender | G11: Appliances | H11: 3 | I11: 59.99 | J11: Cash | K11: West | L11: Premium | M11: 45207 | N11: 179.97
A12: TRX0138 | B12: 45408 | C12: CUST022 | D12: Susan Green | E12: P008 | F12: Bookshelf | G12: Furniture | H12: 1 | I12: 149.99 | J12: Credit Card | K12: West | L12: Standard | M12: 45103 | N12: 149.99
A13: TRX0209 | B13: 45408 | C13: CUST046 | D13: Kathleen Bennett | E13: P008 | F13: Bookshelf | G13: Furniture | H13: 5 | I13: 149.99 | J13: Debit Card | K13: North | L13: Basic | M13: 44830 | N13: 749.95
... A251: TRX0064 | B251: 45758 | C251: CUST031 | D251: Steven Turner | E251: P010 | F251: Keyboard | G251: Electronics | H251: 3 | I251: 89.99 | J251: Debit Card | K251: North | L251: Premium | M251: 44878 | N251: 269.97

Sheet Raw Data
B1: Dataset
B4: Transaction_ID | C4: Date | D4: Customer_ID | E4: Customer_Name | F4: Product_ID | G4: Product_Name | H4: Category | I4: Quantity | J4: Unit_Price | K4: Payment_Method | L4: Region | M4: Customer_Segment | N4: Customer_Since | O4: Total_Amount | P4: MONTH
B5: TRX0155 | C5: 45393 | D5: CUST023 | E5: Paul Baker | F5: P009 | G5: Monitor | H5: Electronics | I5: 3 | J5: 249.99 | K5: Cash | L5: Central | M5: Basic | N5: 44425 | O5: 749.97 | P5: =TEXT(Table2[[#This Row],[Date]], "mm") -> 04
B6: TRX0023 | C6: 45396 | D6: CUST013 | E6: Joseph Jackson | F6: P009 | G6: Monitor | H6: Electronics | I6: 3 | J6: 249.99 | K6: Credit Card | L6: Central | M6: Premium | N6: 44575 | O6: 749.97 | P6: =TEXT(Table2[[#This Row],[Date]], "mm") -> 04
B7: TRX0139 | C7: 45399 | D7: CUST021 | E7: Kevin Scott | F7: P005 | G7: Blender | H7: Appliances | I7: 3 | J7: 59.99 | K7: PayPal | L7: South | M7: Standard | N7: 45262 | O7: 179.97 | P7: =TEXT(Table2[[#This Row],[Date]], "mm") -> 04
B8: TRX0043 | C8: 45400 | D8: CUST046 | E8: Kathleen Bennett | F8: P005 | G8: Blender | H8: Appliances | I8: 3 | J8: 59.99 | K8: Cash | L8: North | M8: Premium | N8: 45114 | O8: 179.97 | P8: =TEXT(Table2[[#This Row],[Date]], "mm") -> 04
B9: TRX0212 | C9: 45400 | D9: CUST003 | E9: Michael Brown | F9: P008 | G9: Bookshelf | H9: Furniture | I9: 5 | J9: 149.99 | K9: Credit Card | L9: North | M9: Premium | N9: 45295 | O9: 749.95 | P9: =TEXT(Table2[[#This Row],[Date]], "mm") -> 04
B10: TRX0092 | C10: 45403 | D10: CUST024 | E10: Dorothy Nelson | F10: P005 | G10: Blender | H10: Appliances | I10: 2 | J10: 59.99 | K10: Cash | L10: West | M10: Standard | N10: 44746 | O10: 119.98 | P10: =TEXT(Table2[[#This Row],[Date]], "mm") -> 04
B11: TRX0193 | C11: 45403 | D11: CUST024 | E11: Dorothy Nelson | F11: P003 | G11: Headphones | H11: Electronics | I11: 5 | J11: 149.99 | K11: Credit Card | L11: Central | M11: Standard | N11: 44418 | O11: 749.95 | P11: =TEXT(Table2[[#This Row],[Date]], "mm") -> 04
B12: TRX0240 | C12: 45403 | D12: CUST017 | E12: Charles Allen | F12: P005 | G12: Blender | H12: Appliances | I12: 3 | J12: 59.99 | K12: Debit Card | L12: South | M12: Basic | N12: 45007 | O12: 179.97 | P12: =TEXT(Table2[[#This Row],[Date]], "mm") -> 04
B13: TRX0135 | C13: 45405 | D13: CUST009 | E13: Robert Thomas | F13: P001 | G13: Laptop | H13: Electronics | I13: 3 | J13: 899.99 | K13: PayPal | L13: East | M13: Standard | N13: 45299 | O13: 2699.97 | P13: =TEXT(Table2[[#This Row],[Date]], "mm") -> 04
B14: TRX0185 | C14: 45408 | D14: CUST026 | E14: Karen Hill | F14: P005 | G14: Blender | H14: Appliances | I14: 3 | J14: 59.99 | K14: Cash | L14: West | M14: Premium | N14: 45207 | O14: 179.97 | P14: =TEXT(Table2[[#This Row],[Date]], "mm") -> 04
B15: TRX0138 | C15: 45408 | D15: CUST022 | E15: Susan Green | F15: P008 | G15: Bookshelf | H15: Furniture | I15: 1 | J15: 149.99 | K15: Credit Card | L15: West | M15: Standard | N15: 45103 | O15: 149.99 | P15: =TEXT(Table2[[#This Row],[Date]], "mm") -> 04
B16: TRX0209 | C16: 45408 | D16: CUST046 | E16: Kathleen Bennett | F16: P008 | G16: Bookshelf | H16: Furniture | I16: 5 | J16: 149.99 | K16: Debit Card | L16: North | M16: Basic | N16: 44830 | O16: 749.95 | P16: =TEXT(Table2[[#This Row],[Date]], "mm") -> 04
... B254: TRX0064 | C254: 45758 | D254: CUST031 | E254: Steven Turner | F254: P010 | G254: Keyboard | H254: Electronics | I254: 3 | J254: 89.99 | K254: Debit Card | L254: North | M254: Premium | N254: 44878 | O254: 269.97 | P254: =TEXT(Table2[[#This Row],[Date]], "mm") -> 04

Sheet Analysis
B2: Date & Time Function
C5: 1. TODAY | E5: 2. Now | G5: 3. DATEDIF | I5: 4. EOMONTH
C7: =TODAY() -> 46182 | E7: =NOW() -> 46182.447 | G7: {=Table2[Date] - Table2[Customer_Since]} -> 968 | I7: =EOMONTH('Raw Data'!N5, 0) -> 44439
G8: 821 | I8: =EOMONTH('Raw Data'!N6, 0) -> 44592
G9: 137 | I9: =EOMONTH('Raw Data'!N7, 0) -> 45291
G10: 286 | I10: =EOMONTH('Raw Data'!N8, 0) -> 45138
G11: 105 | I11: =EOMONTH('Raw Data'!N9, 0) -> 45322
G12: 657 | I12: =EOMONTH('Raw Data'!N10, 0) -> 44773
G13: 985 | I13: =EOMONTH('Raw Data'!N11, 0) -> 44439
G14: 396 | I14: =EOMONTH('Raw Data'!N12, 0) -> 45016
G15: 106 | I15: =EOMONTH('Raw Data'!N13, 0) -> 45322
G16: 201 | I16: =EOMONTH('Raw Data'!N14, 0) -> 45230
G17: 305 | I17: =EOMONTH('Raw Data'!N15, 0) -> 45107
G18: 578 | I18: =EOMONTH('Raw Data'!N16, 0) -> 44834
G19: 602 | I19: =EOMONTH('Raw Data'!N17, 0) -> 44834
... G256: 880 | I256: =EOMONTH('Raw Data'!N254, 0) -> 44895
B261: Filter Function
C264: 1. Filter the Rows where Category is "Electronics" and Region is "West". | S264: 2. Filter the Rows where Customer Segment is "Premium".
C266: {=_xlfn._xlws.FILTER(Table2[[Transaction_ID]:[Customer_Since]], (Table2[Category] = "Electronics") * (Table2[Region] = "West"))} -> TRX0191 | D266: 45409 | E266: CUST038 | F266: Michelle Rogers | G266: P002 | H266: Smartphone | I266: Electronics | J266: 3 | K266: 699.99 | L266: Credit Card | M266: West | N266: Basic | O266: 44577 | S266: {=_xlfn._xlws.FILTER(Table2[[Transaction_ID]:[Total_Amount]], Table2[Customer_Segment] = "Premium")} -> TRX0023 | T266: 45396 | U266: CUST013 | V266: Joseph Jackson | W266: P009 | X266: Monitor | Y266: Electronics | Z266: 3 | AA266: 249.99 | AB266: Credit Card | AC266: Central | AD266: Premium | AE266: 44575 | AF266: 749.97
C267: TRX0122 | D267: 45410 | E267: CUST025 | F267: Mark Carter | G267: P001 | H267: Laptop | I267: Electronics | J267: 4 | K267: 899.99 | L267: Credit Card | M267: West | N267: Standard | O267: 45327 | S267: TRX0043 | T267: 45400 | U267: CUST046 | V267: Kathleen Bennett | W267: P005 | X267: Blender | Y267: Appliances | Z267: 3 | AA267: 59.99 | AB267: Cash | AC267: North | AD267: Premium | AE267: 45114 | AF267: 179.97
C268: TRX0231 | D268: 45412 | E268: CUST018 | F268: Barbara Young | G268: P002 | H268: Smartphone | I268: Electronics | J268: 5 | K268: 699.99 | L268: Cash | M268: West | N268: Basic | O268: 45167 | S268: TRX0212 | T268: 45400 | U268: CUST003 | V268: Michael Brown | W268: P008 | X268: Bookshelf | Y268: Furniture | Z268: 5 | AA268: 149.99 | AB268: Credit Card | AC268: North | AD268: Premium | AE268: 45295 | AF268: 749.95
C269: TRX0071 | D269: 45422 | E269: CUST036 | F269: Nancy Collins | G269: P009 | H269: Monitor | I269: Electronics | J269: 5 | K269: 249.99 | L269: Credit Card | M269: West | N269: Standard | O269: 44525 | S269: TRX0185 | T269: 45408 | U269: CUST026 | V269: Karen Hill | W269: P005 | X269: Blender | Y269: Appliances | Z269: 3 | AA269: 59.99 | AB269: Cash | AC269: West | AD269: Premium | AE269: 45207 | AF269: 179.97
C270: TRX0041 | D270: 45432 | E270: CUST021 | F270: Kevin Scott | G270: P001 | H270: Laptop | I270: Electronics | J270: 1 | K270: 899.99 | L270: Credit Card | M270: West | N270: Premium | O270: 44578 | S270: TRX0246 | T270: 45408 | U270: CUST041 | V270: Peter Richardson | W270: P008 | X270: Bookshelf | Y270: Furniture | Z270: 3 | AA270: 149.99 | AB270: Cash | AC270: North | AD270: Premium | AE270: 44806 | AF270: 449.97
C271: TRX0015 | D271: 45440 | E271: CUST008 | F271: Jennifer Taylor | G271: P002 | H271: Smartphone | I271: Electronics | J271: 5 | K271: 699.99 | L271: PayPal | M271: West | N271: Standard | O271: 44407 | S271: TRX0049 | T271: 45410 | U271: CUST025 | V271: Mark Carter | W271: P008 | X271: Bookshelf | Y271: Furniture | Z271: 4 | AA271: 149.99 | AB271: Debit Card | AC271: North | AD271: Premium | AE271: 45374 | AF271: 599.96
C272: TRX0007 | D272: 45469 | E272: CUST009 | F272: Robert Thomas | G272: P010 | H272: Keyboard | I272: Electronics | J272: 2 | K272: 89.99 | L272: Cash | M272: West | N272: Basic | O272: 44438 | S272: TRX0222 | T272: 45410 | U272: CUST048 | V272: Virginia Sanders | W272: P009 | X272: Monitor | Y272: Electronics | Z272: 3 | AA272: 249.99 | AB272: Credit Card | AC272: North | AD272: Premium | AE272: 45224 | AF272: 749.97
C273: TRX0192 | D273: 45475 | E273: CUST017 | F273: Charles Allen | G273: P010 | H273: Keyboard | I273: Electronics | J273: 1 | K273: 89.99 | L273: PayPal | M273: West | N273: Standard | O273: 44802 | S273: TRX0242 | T273: 45416 | U273: CUST025 | V273: Mark Carter | W273: P007 | X273: Desk | Y273: Furniture | Z273: 4 | AA273: 299.99 | AB273: Cash | AC273: West | AD273: Premium | AE273: 44716 | AF273: 1199.96
C274: TRX0170 | D274: 45532 | E274: CUST034 | F274: Carol Evans | G274: P003 | H274: Headphones | I274: Electronics | J274: 3 | K274: 149.99 | L274: Cash | M274: West | N274: Premium | O274: 45212 | S274: TRX0235 | T274: 45424 | U274: CUST014 | V274: Linda Martin | W274: P004 | X274: Coffee Maker | Y274: Appliances | Z274: 3 | AA274: 79.99 | AB274: PayPal | AC274: East | AD274: Premium | AE274: 45012 | AF274: 239.97
C275: TRX0099 | D275: 45537 | E275: CUST034 | F275: Carol Evans | G275: P009 | H275: Monitor | I275: Electronics | J275: 1 | K275: 249.99 | L275: Credit Card | M275: West | N275: Premium | O275: 44685 | S275: TRX0004 | T275: 45424 | U275: CUST012 | V275: Patricia Moore | W275: P010 | X275: Keyboard | Y275: Electronics | Z275: 5 | AA275: 89.99 | AB275: Cash | AC275: North | AD275: Premium | AE275: 44919 | AF275: 449.95
C276: TRX0158 | D276: 45579 | E276: CUST027 | F276: George Adams | G276: P001 | H276: Laptop | I276: Electronics | J276: 3 | K276: 899.99 | L276: PayPal | M276: West | N276: Basic | O276: 45215 | S276: TRX0130 | T276: 45430 | U276: CUST002 | V276: Emma Wilson | W276: P008 | X276: Bookshelf | Y276: Furniture | Z276: 3 | AA276: 149.99 | AB276: Credit Card | AC276: West | AD276: Premium | AE276: 45068 | AF276: 449.97
C277: TRX0190 | D277: 45583 | E277: CUST039 | F277: Lawrence Reed | G277: P003 | H277: Headphones | I277: Electronics | J277: 2 | K277: 149.99 | L277: Credit Card | M277: West | N277: Basic | O277: 44916 | S277: TRX0041 | T277: 45432 | U277: CUST021 | V277: Kevin Scott | W277: P001 | X277: Laptop | Y277: Electronics | Z277: 1 | AA277: 899.99 | AB277: Credit Card | AC277: West | AD277: Premium | AE277: 44578 | AF277: 899.99
C278: TRX0076 | D278: 45607 | E278: CUST012 | F278: Patricia Moore | G278: P009 | H278: Monitor | I278: Electronics | J278: 4 | K278: 249.99 | L278: Credit Card | M278: West | N278: Standard | O278: 44659 | S278: TRX0245 | T278: 45438 | U278: CUST031 | V278: Steven Turner | W278: P006 | X278: Office Chair | Y278: Furniture | Z278: 3 | AA278: 199.99 | AB278: Credit Card | AC278: North | AD278: Premium | AE278: 45292 | AF278: 599.97
... C287: TRX0250 | D287: 45746 | E287: CUST026 | F287: Karen Hill | G287: P010 | H287: Keyboard | I287: Electronics | J287: 2 | K287: 89.99 | L287: Debit Card | M287: West | N287: Premium | O287: 44522 | S287: TRX0104 | T287: 45471 | U287: CUST012 | V287: Patricia Moore | W287: P001 | X287: Laptop | Y287: Electronics | Z287: 4 | AA287: 899.99 | AB287: Credit Card | AC287: East | AD287: Premium | AE287: 44993 | AF287: 3599.96
S288: TRX0096 | T288: 45474 | U288: CUST002 | V288: Emma Wilson | W288: P010 | X288: Keyboard | Y288: Electronics | Z288: 2 | AA288: 89.99 | AB288: PayPal | AC288: Central | AD288: Premium | AE288: 45275 | AF288: 179.98
S289: TRX0113 | T289: 45481 | U289: CUST003 | V289: Michael Brown | W289: P002 | X289: Smartphone | Y289: Electronics | Z289: 2 | AA289: 699.99 | AB289: PayPal | AC289: East | AD289: Premium | AE289: 45389 | AF289: 1399.98
S290: TRX0114 | T290: 45481 | U290: CUST018 | V290: Barbara Young | W290: P010 | X290: Keyboard | Y290: Electronics | Z290: 5 | AA290: 89.99 | AB290: Debit Card | AC290: North | AD290: Premium | AE290: 45161 | AF290: 449.95
S291: TRX0141 | T291: 45484 | U291: CUST033 | V291: Frank Torres | W291: P007 | X291: Desk | Y291: Furniture | Z291: 1 | AA291: 299.99 | AB291: Credit Card | AC291: North | AD291: Premium | AE291: 44891 | AF291: 299.99
S292: TRX0216 | T292: 45490 | U292: CUST041 | V292: Peter Richardson | W292: P008 | X292: Bookshelf | Y292: Furniture | Z292: 3 | AA292: 149.99 | AB292: Cash | AC292: Central | AD292: Premium | AE292: 45199 | AF292: 449.97
S293: TRX0131 | T293: 45491 | U293: CUST026 | V293: Karen Hill | W293: P006 | X293: Office Chair | Y293: Furniture | Z293: 3 | AA293: 199.99 | AB293: Cash | AC293: North | AD293: Premium | AE293: 45254 | AF293: 599.97
S294: TRX0080 | T294: 45500 | U294: CUST018 | V294: Barbara Young | W294: P009 | X294: Monitor | Y294: Electronics | Z294: 2 | AA294: 249.99 | AB294: Cash | AC294: North | AD294: Premium | AE294: 45164 | AF294: 499.98
S295: TRX0217 | T295: 45503 | U295: CUST025 | V295: Mark Carter | W295: P002 | X295: Smartphone | Y295: Electronics | Z295: 2 | AA295: 699.99 | AB295: Credit Card | AC295: North | AD295: Premium | AE295: 44999 | AF295: 1399.98
...

Sheet Scenario Summary
B2: Scenario Summary
D3: Current Values: | E3: Best Case | F3: Average Case | G3: Worst Case
E4: Created by Lenovo on 29-05-2026 | F4: Created by Lenovo on 29-05-2026 | G4: Created by Lenovo on 29-05-2026
B5: Changing Cells:
C6: $I$407 | D6: 7 | E6: 7 | F6: 5 | G6: 3
C7: $I$408 | D7: 1200 | E7: 1200 | F7: 1000 | G7: 800
B8: Result Cells:
C9: $I$409 | D9: 8400 | E9: 8400 | F9: 5000 | G9: 2400
B10: Notes: Current Values column represents values of changing cells at
B11: time Scenario Summary Report was created. Changing cells for each
B12: scenario are highlighted in gray.

Sheet Linear Regression
A1: SUMMARY OUTPUT
A3: Regression Statistics
A4: Multiple R | B4: 0.45808036
A5: R Square | B5: 0.20983762
A6: Adjusted R Square | B6: 0.20665148
A7: Standard Error | B7: 919.60715
A8: Observations | B8: 250
A10: ANOVA
B11: df | C11: SS | D11: MS | E11: F | F11: Significance F
A12: Regression | B12: 1 | C12: 55695917 | D12: 55695917 | E12: 65.859537 | F12: 2.2586479e-14
A13: Residual | B13: 248 | C13: 2.0972797e+08 | D13: 845677.32
A14: Total | B14: 249 | C14: 2.6542389e+08
B16: Coefficients | C16: Standard Error | D16: t Stat | E16: P-value | F16: Lower 95% | G16: Upper 95% | H16: Lower 95.0% | I16: Upper 95.0%
A17: Intercept | B17: -148.85465 | C17: 143.61334 | D17: -1.0364959 | E17: 0.3009804 | F17: -431.712 | G17: 134.0027 | H17: -431.712 | I17: 134.0027
A18: X Variable 1 | B18: 353.793 | C18: 43.595323 | D18: 8.1153889 | E18: 2.2586479e-14 | F18: 267.92872 | G18: 439.65729 | H18: 267.92872 | I18: 439.65729

Sheet KPI
B3: Total Revenue | G3: Total Orders
B5: =SUM('Raw Data'!O5:O254) -> 229192.47 | G5: =COUNTA(Table2[Transaction_ID]) -> 250
B9: Total Customers | G9: Highest Customer Revenue
B11: =COUNTA(_xlfn.UNIQUE('Raw Data'!D5:D254)) -> 50
G12: =_xlfn.XLOOKUP(MAX(Table2[Total_Amount]), Table2[Total_Amount], Table2[Customer_Name]) -> Paul Baker | H12: =MAX('Raw Data'!O5:O254) -> 4499.95

Sheet Visualization
B2: Most Product Sold
B4: Row Labels | C4: Sum of Quantity
B5: Blender | C5: 87
B6: Bookshelf | C6: 102
B7: Coffee Maker | C7: 39
B8: Desk | C8: 78
B9: Headphones | C9: 47
B10: Keyboard | C10: 89
B11: Laptop | C11: 75
B12: Monitor | C12: 88
B13: Office Chair | C13: 52
B14: Smartphone | C14: 96
B15: Grand Total | C15: 753
B24: Total Revenue Per Category
B26: Row Labels | C26: Sum of Total_Amount
B27: Appliances | C27: 8338.74
B28: Electronics | C28: 171756.05
B29: Furniture | C29: 49097.68
B30: Grand Total | C30: 229192.47
B46: Monthly Revenue Trend
B48: Row Labels | C48: Sum of Total_Amount
B49: 01 | C49: 25799.15
B50: 02 | C50: 16069.38
B51: 03 | C51: 19899.38
B52: 04 | C52: 27899.16
B53: 05 | C53: 17039.35
B54: 06 | C54: 19299.45
B55: 07 | C55: 18479.4
B56: 08 | C56: 15759.43
B57: 09 | C57: 12989.51
B58: 10 | C58: 20609.52
B59: 11 | C59: 12309.44
B60: 12 | C60: 23039.3
B61: Grand Total | C61: 229192.47
B70: Total Revenue
B72: =SUM('Raw Data'!O5:O254) -> 229192.47
B78: Top 5 Customer
B80: Row Labels | C80: Sum of Total_Amount
B81: CUST012 | C81: 9799.73
B82: CUST018 | C82: 10649.8
...

Sheet Dashboard
B2: Amazone Sales Dashboard
F6: Total Revenue | I6: Total Orders | L6: Total Customers | O6: Average Order Value
F7: =SUM('Raw Data'!O7:O256) -> 227692.53 | I7: =COUNTA(Table2[Transaction_ID]) -> 250 | L7: =COUNTA(_xlfn.UNIQUE('Raw Data'!D5:D254)) -> 50 | O7: =SUM('Raw Data'!O5:O254) / COUNTA('Raw Data'!D5:D254) -> 916.76988
B37: The Most Sold Product is : Bookshelf -> 102 Quantity Sold | J37: The Highest Revenue Category is : Electronics -> 75%
B38: The Lowest Sold Product is : Cooffee Maker -> 39 Quantity Sold Only | J38: The Lowest Revenue Category is : Appliances -> 4% Only
B60: We Got the Highest Revenue in the Month of "4th" : April -> 27,899.16
B61: Also We got the Lowest Revenue in the Month of "11th" : November -> 12,309.44 Only

Sheet Sheet1
